Workbook

Sheet ANÁLISE CONSUMO
A1: CONSUMO PONTA (Kwh)
B2: JAN | C2: FEV | D2: MAR | E2: ABR | F2: MAI | G2: JUN | H2: JUL | I2: AGO | J2: SET | K2: OUT | L2: NOV | M2: DEZ
A3: AREOLINO DE ABREU | B3: =#REF! -> #REF! | C3: =#REF! -> #REF! | D3: =#REF! -> #REF! | E3: =#REF! -> #REF! | F3: =#REF! -> #REF! | G3: =#REF! -> #REF! | H3: =#REF! -> #REF! | I3: =#REF! -> #REF! | ... M3: =#REF! -> #REF!
A4: BENTO LEÃO 25 | B4: =#REF! -> #REF! | C4: =#REF! -> #REF! | D4: =#REF! -> #REF! | E4: =#REF! -> #REF! | F4: =#REF! -> #REF! | G4: =#REF! -> #REF! | H4: =#REF! -> #REF! | I4: =#REF! -> #REF! | ... M4: =#REF! -> #REF!
A5: BENTO LEÃO 25A | B5: =#REF! -> #REF! | C5: =#REF! -> #REF! | D5: =#REF! -> #REF! | E5: =#REF! -> #REF! | F5: =#REF! -> #REF! | G5: =#REF! -> #REF! | H5: =#REF! -> #REF! | I5: =#REF! -> #REF! | ... M5: =#REF! -> #REF!
A6: TOTAL | B6: =SUM(B3:B5) -> #REF! | C6: =SUM(C3:C5) -> #REF! | D6: =SUM(D3:D5) -> #REF! | E6: =SUM(E3:E5) -> #REF! | F6: =SUM(F3:F5) -> #REF! | G6: =SUM(G3:G5) -> #REF! | H6: =SUM(H3:H5) -> #REF! | I6: =SUM(I3:I5) -> #REF! | ... M6: =SUM(M3:M5) -> #REF!
A8: VALOR CONSUMO PONTA (R$)
B9: JAN | C9: FEV | D9: MAR | E9: ABR | F9: MAI | G9: JUN | H9: JUL | I9: AGO | J9: SET | K9: OUT | L9: NOV | M9: DEZ
A10: AREOLINO DE ABREU | B10: =#REF! -> #REF! | C10: =#REF! -> #REF! | D10: =#REF! -> #REF! | E10: =#REF! -> #REF! | F10: =#REF! -> #REF! | G10: =#REF! -> #REF! | H10: =#REF! -> #REF! | I10: =#REF! -> #REF! | ... M10: =#REF! -> #REF!
A11: BENTO LEÃO 25 | B11: =#REF! -> #REF! | C11: =#REF! -> #REF! | D11: =#REF! -> #REF! | E11: =#REF! -> #REF! | F11: =#REF! -> #REF! | G11: =#REF! -> #REF! | H11: =#REF! -> #REF! | I11: =#REF! -> #REF! | ... M11: =#REF! -> #REF!
A12: BENTO LEÃO 25A | B12: =#REF! -> #REF! | C12: =#REF! -> #REF! | D12: =#REF! -> #REF! | E12: =#REF! -> #REF! | F12: =#REF! -> #REF! | G12: =#REF! -> #REF! | H12: =#REF! -> #REF! | I12: =#REF! -> #REF! | ... M12: =#REF! -> #REF!
A13: TOTAL | B13: =SUM(B10:B12) -> #REF! | C13: =SUM(C10:C12) -> #REF! | D13: =SUM(D10:D12) -> #REF! | E13: =SUM(E10:E12) -> #REF! | F13: =SUM(F10:F12) -> #REF! | G13: =SUM(G10:G12) -> #REF! | H13: =SUM(H10:H12) -> #REF! | I13: =SUM(I10:I12) -> #REF! | ... M13: =SUM(M10:M12) -> #REF!
A17: CONSUMO NORMAL (Kwh)
B18: JAN | C18: FEV | D18: MAR | E18: ABR | F18: MAI | G18: JUN | H18: JUL | I18: AGO | J18: SET | K18: OUT | L18: NOV | M18: DEZ
A19: AREOLINO DE ABREU | B19: =#REF! -> #REF! | C19: =#REF! -> #REF! | D19: =#REF! -> #REF! | E19: =#REF! -> #REF! | F19: =#REF! -> #REF! | G19: =#REF! -> #REF! | H19: =#REF! -> #REF! | I19: =#REF! -> #REF! | ... M19: =#REF! -> #REF!
A20: BENTO LEÃO 25 | B20: =#REF! -> #REF! | C20: =#REF! -> #REF! | D20: =#REF! -> #REF! | E20: =#REF! -> #REF! | F20: =#REF! -> #REF! | G20: =#REF! -> #REF! | H20: =#REF! -> #REF! | I20: =#REF! -> #REF! | ... M20: =#REF! -> #REF!
A21: BENTO LEÃO 25A | B21: =#REF! -> #REF! | C21: =#REF! -> #REF! | D21: =#REF! -> #REF! | E21: =#REF! -> #REF! | F21: =#REF! -> #REF! | G21: =#REF! -> #REF! | H21: =#REF! -> #REF! | I21: =#REF! -> #REF! | ... M21: =#REF! -> #REF!
A22: TOTAL | B22: =SUM(B19:B21) -> #REF! | C22: =SUM(C19:C21) -> #REF! | D22: =SUM(D19:D21) -> #REF! | E22: =SUM(E19:E21) -> #REF! | F22: =SUM(F19:F21) -> #REF! | G22: =SUM(G19:G21) -> #REF! | H22: =SUM(H19:H21) -> #REF! | I22: =SUM(I19:I21) -> #REF! | ... M22: =SUM(M19:M21) -> #REF!
A24: VALOR CONSUMO NORMAL (R$)
B25: JAN | C25: FEV | D25: MAR | E25: ABR | F25: MAI | G25: JUN | H25: JUL | I25: AGO | J25: SET | K25: OUT | L25: NOV | M25: DEZ
A26: AREOLINO DE ABREU | B26: =#REF! -> #REF! | C26: =#REF! -> #REF! | D26: =#REF! -> #REF! | E26: =#REF! -> #REF! | F26: =#REF! -> #REF! | G26: =#REF! -> #REF! | H26: =#REF! -> #REF! | I26: =#REF! -> #REF! | ... M26: =#REF! -> #REF!
A27: BENTO LEÃO 25 | B27: =#REF! -> #REF! | C27: =#REF! -> #REF! | D27: =#REF! -> #REF! | E27: =#REF! -> #REF! | F27: =#REF! -> #REF! | G27: =#REF! -> #REF! | H27: =#REF! -> #REF! | I27: =#REF! -> #REF! | ... M27: =#REF! -> #REF!
A28: BENTO LEÃO 25A | B28: =#REF! -> #REF! | C28: =#REF! -> #REF! | D28: =#REF! -> #REF! | E28: =#REF! -> #REF! | F28: =#REF! -> #REF! | G28: =#REF! -> #REF! | H28: =#REF! -> #REF! | I28: =#REF! -> #REF! | ... M28: =#REF! -> #REF!
A29: TOTAL | B29: =SUM(B26:B28) -> #REF! | C29: =SUM(C26:C28) -> #REF! | D29: =SUM(D26:D28) -> #REF! | E29: =SUM(E26:E28) -> #REF! | F29: =SUM(F26:F28) -> #REF! | G29: =SUM(G26:G28) -> #REF! | H29: =SUM(H26:H28) -> #REF! | I29: =SUM(I26:I28) -> #REF! | ... M29: =SUM(M26:M28) -> #REF!
A32: DEMANDA - RUA AREOLINO DE ABREU
A33: CONSUMO | B33: JAN | C33: FEV | D33: MAR | E33: ABR | F33: MAI | G33: JUN | H33: JUL | I33: AGO | J33: SET | K33: OUT | L33: NOV | M33: DEZ
A34: DEMANDA CONTRATADA | B34: 165 | C34: 165 | D34: 165 | E34: 165 | F34: 165 | G34: 165 | H34: 165 | I34: 165 | J34: 165 | K34: 165 | L34: 165 | M34: 165
A35: DEMANDA UTILIZADA | B35: =#REF! -> #REF! | C35: =#REF! -> #REF! | D35: =#REF! -> #REF! | E35: =#REF! -> #REF! | F35: =#REF! -> #REF! | G35: =#REF! -> #REF! | H35: =#REF! -> #REF! | I35: =#REF! -> #REF! | ... M35: =#REF! -> #REF!
A36: DEMANDA EXCEDENTES | B36: =#REF! -> #REF! | C36: =#REF! -> #REF! | D36: =#REF! -> #REF! | E36: =#REF! -> #REF! | F36: =#REF! -> #REF! | G36: =#REF! -> #REF! | H36: =#REF! -> #REF! | I36: =#REF! -> #REF! | ... M36: =#REF! -> #REF!
A37: VALOR | B37: JAN | C37: FEV | D37: MAR | E37: ABR | F37: MAI | G37: JUN | H37: JUL | I37: AGO | J37: SET | K37: OUT | L37: NOV | M37: DEZ
A38: DEMANDA UTILIZADA | B38: =#REF! -> #REF! | C38: =#REF! -> #REF! | D38: =#REF! -> #REF! | E38: =#REF! -> #REF! | F38: =#REF! -> #REF! | G38: =#REF! -> #REF! | H38: =#REF! -> #REF! | I38: =#REF! -> #REF! | ... M38: =#REF! -> #REF!
A39: DEMANDA EXCEDENTES | B39: =#REF! -> #REF! | C39: =#REF! -> #REF! | D39: =#REF! -> #REF! | E39: =#REF! -> #REF! | F39: =#REF! -> #REF! | G39: =#REF! -> #REF! | H39: =#REF! -> #REF! | I39: =#REF! -> #REF! | ... M39: =#REF! -> #REF!
A40: TOTAL | B40: =B38+B39 -> #REF! | C40: =C38+C39 -> #REF! | D40: =D38+D39 -> #REF! | E40: =E38+E39 -> #REF! | F40: =F38+F39 -> #REF! | G40: =G38+G39 -> #REF! | H40: =H38+H39 -> #REF! | I40: =I38+I39 -> #REF! | ... M40: =M38+M39 -> #REF!
A42: DEMANDA - RUA BENTO LEÃO 25
A43: CONSUMO | B43: JAN | C43: FEV | D43: MAR | E43: ABR | F43: MAI | G43: JUN | H43: JUL | I43: AGO | J43: SET | K43: OUT | L43: NOV | M43: DEZ
A44: DEMANDA CONTRATADA | B44: 115 | C44: 115 | D44: 115 | E44: 115 | F44: 115 | G44: 115 | H44: 115 | I44: 115 | J44: 115 | K44: 115 | L44: 115 | M44: 115
A45: DEMANDA UTILIZADA | B45: =#REF! -> #REF! | C45: =#REF! -> #REF! | D45: =#REF! -> #REF! | E45: =#REF! -> #REF! | F45: =#REF! -> #REF! | G45: =#REF! -> #REF! | H45: =#REF! -> #REF! | I45: =#REF! -> #REF! | ... M45: =#REF! -> #REF!
A46: DEMANDA EXCEDENTES | B46: =#REF! -> #REF! | C46: =#REF! -> #REF! | D46: =#REF! -> #REF! | E46: =#REF! -> #REF! | F46: =#REF! -> #REF! | G46: =#REF! -> #REF! | H46: =#REF! -> #REF! | I46: =#REF! -> #REF! | ... M46: =#REF! -> #REF!
A47: VALOR | B47: JAN | C47: FEV | D47: MAR | E47: ABR | F47: MAI | G47: JUN | H47: JUL | I47: AGO | J47: SET | K47: OUT | L47: NOV | M47: DEZ
A48: DEMANDA UTILIZADA | B48: =#REF! -> #REF! | C48: =#REF! -> #REF! | D48: =#REF! -> #REF! | E48: =#REF! -> #REF! | F48: =#REF! -> #REF! | G48: =#REF! -> #REF! | H48: =#REF! -> #REF! | I48: =#REF! -> #REF! | ... M48: =#REF! -> #REF!
...

Sheet Planilha1
A1: DEMANDA - EQUATORIAL ENERGIA
A2: CONSUMO | B2: JAN | C2: FEV | D2: MAR | E2: ABR | F2: MAI | G2: JUN | H2: JUL | I2: AGO | J2: SET | K2: OUT | L2: NOV | M2: DEZ
A3: AREOLINO DE ABREU | B3: ='ANÁLISE CONSUMO'!B40 -> #REF! | C3: ='ANÁLISE CONSUMO'!C40 -> #REF! | D3: ='ANÁLISE CONSUMO'!D40 -> #REF! | E3: ='ANÁLISE CONSUMO'!E40 -> #REF! | F3: ='ANÁLISE CONSUMO'!F40 -> #REF! | G3: ='ANÁLISE CONSUMO'!G40 -> #REF! | H3: ='ANÁLISE CONSUMO'!H40 -> #REF! | I3: ='ANÁLISE CONSUMO'!I40 -> #REF! | ... L3: ='ANÁLISE CONSUMO'!L40 -> #REF!
A4: BENTO LEÃO 25 | B4: ='ANÁLISE CONSUMO'!B50 -> #REF! | C4: ='ANÁLISE CONSUMO'!C50 -> #REF! | D4: ='ANÁLISE CONSUMO'!D50 -> #REF! | E4: ='ANÁLISE CONSUMO'!E50 -> #REF! | F4: ='ANÁLISE CONSUMO'!F50 -> #REF! | G4: ='ANÁLISE CONSUMO'!G50 -> #REF! | H4: ='ANÁLISE CONSUMO'!H50 -> #REF! | I4: ='ANÁLISE CONSUMO'!I50 -> #REF! | ... L4: ='ANÁLISE CONSUMO'!L50 -> #REF!
A5: BENTO LEÃO 25 A | B5: =B3+B4 -> #REF! | C5: =C3+C4 -> #REF! | D5: =D3+D4 -> #REF! | E5: =E3+E4 -> #REF! | F5: =F3+F4 -> #REF! | G5: =G3+G4 -> #REF! | H5: =H3+H4 -> #REF! | I5: =I3+I4 -> #REF! | ... L5: =L3+L4 -> #REF!
A6: VALOR | B6: =SUM(B3:B5) -> #REF! | C6: =SUM(C3:C5) -> #REF! | D6: =SUM(D3:D5) -> #REF! | E6: =SUM(E3:E5) -> #REF! | F6: =SUM(F3:F5) -> #REF! | G6: =SUM(G3:G5) -> #REF! | H6: =SUM(H3:H5) -> #REF! | I6: =SUM(I3:I5) -> #REF! | ... L6: =SUM(L3:L5) -> #REF!
A9: DEMANDA - EQUATORIAL ENERGIA - (50% INCENTIVO ENERGIA LIMPA)
A10: CONSUMO | B10: JAN | C10: FEV | D10: MAR | E10: ABR | F10: MAI | G10: JUN | H10: JUL | I10: AGO | J10: SET | K10: OUT | L10: NOV | M10: DEZ
A11: AREOLINO DE ABREU | B11: =B3*50% -> #REF! | C11: =C3*50% -> #REF! | D11: =D3*50% -> #REF! | E11: =E3*50% -> #REF! | F11: =F3*50% -> #REF! | G11: =G3*50% -> #REF! | H11: =H3*50% -> #REF! | I11: =I3*50% -> #REF! | ... L11: =L3*50% -> #REF!
A12: BENTO LEÃO 25 | B12: =B4*50% -> #REF! | C12: =C4*50% -> #REF! | D12: =D4*50% -> #REF! | E12: =E4*50% -> #REF! | F12: =F4*50% -> #REF! | G12: =G4*50% -> #REF! | H12: =H4*50% -> #REF! | I12: =I4*50% -> #REF! | ... L12: =L4*50% -> #REF!
A13: BENTO LEÃO 25 A | B13: =B5*50% -> #REF! | C13: =C5*50% -> #REF! | D13: =D5*50% -> #REF! | E13: =E5*50% -> #REF! | F13: =F5*50% -> #REF! | G13: =G5*50% -> #REF! | H13: =H5*50% -> #REF! | I13: =I5*50% -> #REF! | ... L13: =L5*50% -> #REF!
A14: VALOR | B14: =SUM(B11:B13) -> #REF! | C14: =SUM(C11:C13) -> #REF! | D14: =SUM(D11:D13) -> #REF! | E14: =SUM(E11:E13) -> #REF! | F14: =SUM(F11:F13) -> #REF! | G14: =SUM(G11:G13) -> #REF! | H14: =SUM(H11:H13) -> #REF! | I14: =SUM(I11:I13) -> #REF! | ... L14: =SUM(L11:L13) -> #REF!
A20: VALOR CONSUMO NORMAL (R$)
B21: JAN | C21: FEV | D21: MAR | E21: ABR | F21: MAI | G21: JUN | H21: JUL | I21: AGO | J21: SET | K21: OUT | L21: NOV | M21: DEZ
A22: AREOLINO DE ABREU | B22: ='ANÁLISE CONSUMO'!B26 -> #REF! | C22: ='ANÁLISE CONSUMO'!C26 -> #REF! | D22: ='ANÁLISE CONSUMO'!D26 -> #REF! | E22: ='ANÁLISE CONSUMO'!E26 -> #REF! | F22: ='ANÁLISE CONSUMO'!F26 -> #REF! | G22: ='ANÁLISE CONSUMO'!G26 -> #REF! | H22: ='ANÁLISE CONSUMO'!H26 -> #REF! | I22: ='ANÁLISE CONSUMO'!I26 -> #REF! | ... L22: ='ANÁLISE CONSUMO'!L26 -> #REF! | M22: =#REF! -> #REF!
A23: BENTO LEÃO 25 | B23: ='ANÁLISE CONSUMO'!B27 -> #REF! | C23: ='ANÁLISE CONSUMO'!C27 -> #REF! | D23: ='ANÁLISE CONSUMO'!D27 -> #REF! | E23: ='ANÁLISE CONSUMO'!E27 -> #REF! | F23: ='ANÁLISE CONSUMO'!F27 -> #REF! | G23: ='ANÁLISE CONSUMO'!G27 -> #REF! | H23: ='ANÁLISE CONSUMO'!H27 -> #REF! | I23: ='ANÁLISE CONSUMO'!I27 -> #REF! | ... L23: ='ANÁLISE CONSUMO'!L27 -> #REF! | M23: =#REF! -> #REF!
A24: BENTO LEÃO 25A | B24: ='ANÁLISE CONSUMO'!B28 -> #REF! | C24: ='ANÁLISE CONSUMO'!C28 -> #REF! | D24: ='ANÁLISE CONSUMO'!D28 -> #REF! | E24: ='ANÁLISE CONSUMO'!E28 -> #REF! | F24: ='ANÁLISE CONSUMO'!F28 -> #REF! | G24: ='ANÁLISE CONSUMO'!G28 -> #REF! | H24: ='ANÁLISE CONSUMO'!H28 -> #REF! | I24: ='ANÁLISE CONSUMO'!I28 -> #REF! | ... L24: ='ANÁLISE CONSUMO'!L28 -> #REF! | M24: =#REF! -> #REF!
A25: TOTAL | B25: =SUM(B22:B24) -> #REF! | C25: =SUM(C22:C24) -> #REF! | D25: =SUM(D22:D24) -> #REF! | E25: =SUM(E22:E24) -> #REF! | F25: =SUM(F22:F24) -> #REF! | G25: =SUM(G22:G24) -> #REF! | H25: =SUM(H22:H24) -> #REF! | I25: =SUM(I22:I24) -> #REF! | ... M25: =SUM(M22:M24) -> #REF!
A27: VALOR CONSUMO HORA PONTA (R$)
B28: JAN | C28: FEV | D28: MAR | E28: ABR | F28: MAI | G28: JUN | H28: JUL | I28: AGO | J28: SET | K28: OUT | L28: NOV | M28: DEZ
A29: AREOLINO DE ABREU | B29: ='ANÁLISE CONSUMO'!B10 -> #REF! | C29: ='ANÁLISE CONSUMO'!C10 -> #REF! | D29: ='ANÁLISE CONSUMO'!D10 -> #REF! | E29: ='ANÁLISE CONSUMO'!E10 -> #REF! | F29: ='ANÁLISE CONSUMO'!F10 -> #REF! | G29: ='ANÁLISE CONSUMO'!G10 -> #REF! | H29: ='ANÁLISE CONSUMO'!H10 -> #REF! | I29: ='ANÁLISE CONSUMO'!I10 -> #REF! | ... L29: ='ANÁLISE CONSUMO'!L10 -> #REF! | M29: =#REF! -> #REF!
A30: BENTO LEÃO 25 | B30: ='ANÁLISE CONSUMO'!B11 -> #REF! | C30: ='ANÁLISE CONSUMO'!C11 -> #REF! | D30: ='ANÁLISE CONSUMO'!D11 -> #REF! | E30: ='ANÁLISE CONSUMO'!E11 -> #REF! | F30: ='ANÁLISE CONSUMO'!F11 -> #REF! | G30: ='ANÁLISE CONSUMO'!G11 -> #REF! | H30: ='ANÁLISE CONSUMO'!H11 -> #REF! | I30: ='ANÁLISE CONSUMO'!I11 -> #REF! | ... L30: ='ANÁLISE CONSUMO'!L11 -> #REF! | M30: =#REF! -> #REF!
A31: BENTO LEÃO 25A | B31: ='ANÁLISE CONSUMO'!B12 -> #REF! | C31: ='ANÁLISE CONSUMO'!C12 -> #REF! | D31: ='ANÁLISE CONSUMO'!D12 -> #REF! | E31: ='ANÁLISE CONSUMO'!E12 -> #REF! | F31: ='ANÁLISE CONSUMO'!F12 -> #REF! | G31: ='ANÁLISE CONSUMO'!G12 -> #REF! | H31: ='ANÁLISE CONSUMO'!H12 -> #REF! | I31: ='ANÁLISE CONSUMO'!I12 -> #REF! | ... L31: ='ANÁLISE CONSUMO'!L12 -> #REF! | M31: =#REF! -> #REF!
A32: TOTAL | B32: =SUM(B29:B31) -> #REF! | C32: =SUM(C29:C31) -> #REF! | D32: =SUM(D29:D31) -> #REF! | E32: =SUM(E29:E31) -> #REF! | F32: =SUM(F29:F31) -> #REF! | G32: =SUM(G29:G31) -> #REF! | H32: =SUM(H29:H31) -> #REF! | I32: =SUM(I29:I31) -> #REF! | ... M32: =SUM(M29:M31) -> #REF!
A35: TOTAL CONSUMO | B35: =B25+B32 -> #REF! | C35: =C25+C32 -> #REF! | D35: =D25+D32 -> #REF! | E35: =E25+E32 -> #REF! | F35: =F25+F32 -> #REF! | G35: =G25+G32 -> #REF! | H35: =H25+H32 -> #REF! | I35: =I25+I32 -> #REF! | ... M35: =M25+M32 -> #REF!
A36: ECONOMIA - 18,5% | B36: =B35*17.5% -> #REF! | C36: =C35*17.5% -> #REF! | D36: =D35*17.5% -> #REF! | E36: =E35*17.5% -> #REF! | F36: =F35*17.5% -> #REF! | G36: =G35*17.5% -> #REF! | H36: =H35*17.5% -> #REF! | I36: =I35*17.5% -> #REF! | ... L36: =L35*17.5% -> #REF! | M36: =M35*18.5% -> #REF!
A37: ECHOENERGIA | B37: =B35-B36 -> #REF! | C37: =C35-C36 -> #REF! | D37: =D35-D36 -> #REF! | E37: =E35-E36 -> #REF! | F37: =F35-F36 -> #REF! | G37: =G35-G36 -> #REF! | H37: =H35-H36 -> #REF! | I37: =I35-I36 -> #REF! | ... M37: =M35-M36 -> #REF!
A40: CONSUMO ANUAL | B40: =#REF! -> #REF! | C40: =#REF! -> #REF! | D40: =#REF! -> #REF! | E40: =#REF! -> #REF! | F40: =#REF! -> #REF! | G40: =#REF! -> #REF! | H40: =#REF! -> #REF! | I40: =#REF! -> #REF! | ... L40: =#REF! -> #REF!
A43: EQUATORIAL(DEMANDA, IL.PUBLICA E REATIVA) | B43: =B14+1350 -> #REF! | C43: =C14+1350 -> #REF! | D43: =D14+1350 -> #REF! | E43: =E14+1350 -> #REF! | F43: =F14+1350 -> #REF! | G43: =G14+1350 -> #REF! | H43: =H14+1350 -> #REF! | I43: =I14+1350 -> #REF! | ... L43: =L14+1350 -> #REF!
A44: ECHOENERGIA (CONSUMO) | B44: =B37 -> #REF! | C44: =C37 -> #REF! | D44: =D37 -> #REF! | E44: =E37 -> #REF! | F44: =F37 -> #REF! | G44: =G37 -> #REF! | H44: =H37 -> #REF! | I44: =I37 -> #REF! | ... L44: =L37 -> #REF!
A45: TOTAL | B45: =B43+B44 -> #REF! | C45: =C43+C44 -> #REF! | D45: =D43+D44 -> #REF! | E45: =E43+E44 -> #REF! | F45: =F43+F44 -> #REF! | G45: =G43+G44 -> #REF! | H45: =H43+H44 -> #REF! | I45: =I43+I44 -> #REF! | ... L45: =L43+L44 -> #REF!
A46: ECONOMIA ANUAL | B46: =B40-B45 -> #REF! | C46: =C40-C45 -> #REF! | D46: =D40-D45 -> #REF! | E46: =E40-E45 -> #REF! | F46: =F40-F45 -> #REF! | G46: =G40-G45 -> #REF! | H46: =H40-H45 -> #REF! | I46: =I40-I45 -> #REF! | ... L46: =L40-L45 -> #REF!

Sheet ENERGIA 2026- LIVRE (TESTE WEL)
A1: ENERGIA 2026 | H1: ENERGIA 2026 | O1: ENERGIA 2026 | V1: ENERGIA 2026
B2: JANEIRO | E2: TOTAL | F2: CONSUMO | I2: ABRIL | L2: TOTAL | M2: CONSUMO | P2: JULHO | S2: TOTAL | T2: CONSUMO | W2: OUTUBRO | Z2: TOTAL | AA2: CONSUMO
B3: EQUATORIAL | C3: EQUATORIAL RENOVAVEIS S.A | D3: EQUTORIAL RENOVAVEIS S.A (NF SERVIÇO) | I3: EQUATORIAL | J3: EQUATORIAL RENOVAVEIS S.A | K3: EQUTORIAL RENOVAVEIS S.A (NF SERVIÇO) | P3: EQUATORIAL | Q3: EQUATORIAL RENOVAVEIS S.A | R3: EQUTORIAL RENOVAVEIS S.A (NF SERVIÇO) | W3: EQUATORIAL | X3: EQUATORIAL RENOVAVEIS S.A | Y3: EQUTORIAL RENOVAVEIS S.A (NF SERVIÇO)
A4: AREOLINO DE ABREU | B4: 9132.27 | C4: 3600.5 | D4: 3007.78 | E4: =SUM(B4:D4) -> 15740.55 | F4: 16.31754 | H4: AREOLINO DE ABREU | I4: 8554.71 | J4: 3352.83 | K4: 2994.41 | L4: =SUM(I4:K4) -> 14901.95 | M4: 836.20205 | O4: AREOLINO DE ABREU | P4: 13310.88 | Q4: 4986.61 | R4: 3689.22 | S4: =SUM(P4:R4) -> 21986.71 | T4: 20.53148 | V4: AREOLINO DE ABREU | Z4: =SUM(W4:Y4) -> 0
A5: BENTO LEÃO 25 | B5: 8969.62 | C5: 3592.57 | D5: 3047.55 | E5: =SUM(B5:D5) -> 15609.74 | F5: 16.96261 | H5: BENTO LEÃO 25 | I5: 10871.41 | J5: 4265.54 | K5: 3511.24 | L5: =SUM(I5:K5) -> 18648.19 | M5: 19.59442 | O5: BENTO LEÃO 25 | P5: 11177.82 | Q5: 4596.15 | R5: 4342.95 | S5: =SUM(P5:R5) -> 20116.92 | T5: 19.12796 | V5: BENTO LEÃO 25 | Z5: =SUM(W5:Y5) -> 0
A6: BENTO LEÃO 25A | B6: 24013 | C6: 9229.54 | D6: 7622.56 | E6: =SUM(B6:D6) -> 40865.1 | F6: 46.78631 | H6: BENTO LEÃO 25A | I6: 30158.63 | J6: 12076.31 | K6: 9300.14 | L6: =SUM(I6:K6) -> 51535.08 | M6: 58.96159 | O6: BENTO LEÃO 25A | P6: 31820.47 | Q6: 13037.85 | R6: 10236.96 | S6: =SUM(P6:R6) -> 55095.28 | T6: 56.9109 | V6: BENTO LEÃO 25A | Z6: =SUM(W6:Y6) -> 0
A7: TOTAL | B7: =SUM(B4:B6) -> 42114.89 | C7: =SUM(C4:C6) -> 16422.61 | D7: =SUM(D4:D6) -> 13677.89 | E7: =SUM(B7:D7) -> 72215.39 | F7: =SUM(F4:F6) -> 80.06646 | H7: TOTAL | I7: =SUM(I4:I6) -> 49584.75 | J7: =SUM(J4:J6) -> 19694.68 | K7: =SUM(K4:K6) -> 15805.79 | L7: =SUM(I7:K7) -> 85085.22 | M7: =SUM(M4:M6) -> 914.75806 | O7: TOTAL | P7: =SUM(P4:P6) -> 56309.17 | Q7: =SUM(Q4:Q6) -> 22620.61 | R7: =SUM(R4:R6) -> 18269.13 | S7: =SUM(P7:R7) -> 97198.91 | T7: =SUM(T4:T6) -> 96.57034 | V7: TOTAL | W7: =SUM(W5:W6) -> 0 | X7: =SUM(X4:X6) -> 0 | Y7: =SUM(Y4:Y6) -> 0 | Z7: =SUM(W7:Y7) -> 0
E8: KWH | F8: =E7/F7 -> 901.94309 | L8: KWH | M8: =L7/M7 -> 93.013906 | S8: KWH | T8: =S7/T7 -> 1006.5089
A10: ENERGIA 2026 | H10: ENERGIA 2026 | O10: ENERGIA 2026 | V10: ENERGIA 2026
B11: FEVEREIRO | E11: TOTAL | F11: CONSUMO | I11: MAIO | L11: TOTAL | M11: CONSUMO | P11: AGOSTO | S11: TOTAL | T11: CONSUMO | W11: NOVEMBRO | Z11: TOTAL | AA11: CONSUMO
B12: EQUATORIAL | C12: EQUATORIAL RENOVAVEIS S.A | D12: EQUTORIAL RENOVAVEIS S.A (NF SERVIÇO) | I12: EQUATORIAL | J12: EQUATORIAL RENOVAVEIS S.A | K12: EQUTORIAL RENOVAVEIS S.A (NF SERVIÇO) | P12: EQUATORIAL | Q12: EQUATORIAL RENOVAVEIS S.A | R12: EQUTORIAL RENOVAVEIS S.A (NF SERVIÇO) | W12: EQUATORIAL | X12: EQUATORIAL RENOVAVEIS S.A | Y12: EQUTORIAL RENOVAVEIS S.A (NF SERVIÇO)
A13: AREOLINO DE ABREU | B13: 9317.07 | C13: 3799.08 | D13: 3133.6 | E13: =SUM(B13:D13) -> 16249.75 | F13: 16.71293 | H13: AREOLINO DE ABREU | I13: 10906.52 | J13: 4265.21 | K13: 3715.26 | L13: =SUM(I13:K13) -> 18886.99 | M13: 19.6223 | O13: AREOLINO DE ABREU | P13: 13639.91 | Q13: 5015.38 | R13: 3665.07 | S13: =SUM(P13:R13) -> 22320.36 | T13: 20.16377 | V13: AREOLINO DE ABREU | Z13: =SUM(W13:Y13) -> 0
A14: BENTO LEÃO 25 | B14: 10020.32 | C14: 4176.94 | D14: 3380.25 | E14: =SUM(B14:D14) -> 17577.51 | F14: 19.30863 | H14: BENTO LEÃO 25 | I14: 10784.49 | J14: 4623.81 | K14: 3666.24 | L14: =SUM(I14:K14) -> 19074.54 | M14: 17.5436 | O14: BENTO LEÃO 25 | P14: 11060.18 | Q14: 4560.77 | R14: 4253.43 | S14: =SUM(P14:R14) -> 19874.38 | T14: 18.91072 | V14: BENTO LEÃO 25 | Z14: =SUM(W14:Y14) -> 0
A15: BENTO LEÃO 25A | B15: 26386.74 | C15: 10682.86 | D15: 8338.3 | E15: =SUM(B15:C15) -> 37069.6 | F15: 52.14121 | H15: BENTO LEÃO 25A | I15: 27645.34 | J15: 12155.79 | K15: 9270.53 | L15: =SUM(I15:K15) -> 49071.66 | M15: 53.59298 | O15: BENTO LEÃO 25A | P15: 28522.86 | Q15: 11423.33 | R15: 8883.29 | S15: =SUM(P15:R15) -> 48829.48 | T15: 49.80201 | V15: BENTO LEÃO 25A | Z15: =SUM(W15:Y15) -> 0
A16: TOTAL | B16: =SUM(B13:B15) -> 45724.13 | C16: =SUM(C13:C15) -> 18658.88 | D16: =SUM(D13:D15) -> 14852.15 | E16: =SUM(B16:D16) -> 79235.16 | F16: =SUM(F13:F15) -> 88.16277 | H16: TOTAL | I16: =SUM(I13:I15) -> 49336.35 | J16: =SUM(J13:J15) -> 21044.81 | K16: =SUM(K13:K15) -> 16652.03 | L16: =SUM(I16:K16) -> 87033.19 | M16: =SUM(M13:M15) -> 90.75888 | O16: TOTAL | P16: =SUM(P13:P15) -> 53222.95 | Q16: =SUM(Q13:Q15) -> 20999.48 | R16: =SUM(R13:R15) -> 16801.79 | S16: =SUM(P16:R16) -> 91024.22 | T16: =SUM(T13:T15) -> 88.8765 | V16: TOTAL | W16: =SUM(W14:W15) -> 0 | X16: =SUM(X13:X15) -> 0 | Y16: =SUM(Y14:Y15) -> 0 | Z16: =SUM(W16:Y16) -> 0
E17: KWH | F17: =E16/F16 -> 898.73719 | L17: KWH | M17: =L16/M16 -> 958.94958 | S17: KWH | T17: =S16/T16 -> 1024.1652
A19: ENERGIA 2026 | H19: ENERGIA 2026 | O19: ENERGIA 2026 | V19: ENERGIA 2026
B20: MARÇO | E20: TOTAL | F20: CONSUMO | I20: JUNHO | L20: TOTAL | M20: CONSUMO | P20: SETEMBRO | S20: TOTAL | T20: CONSUMO | W20: DEZEMBRO | Z20: TOTAL | AA20: CONSUMO
B21: EQUATORIAL | C21: EQUATORIAL RENOVAVEIS S.A | D21: EQUTORIAL RENOVAVEIS S.A (NF SERVIÇO) | I21: EQUATORIAL | J21: EQUATORIAL RENOVAVEIS S.A | K21: EQUTORIAL RENOVAVEIS S.A (NF SERVIÇO) | P21: EQUATORIAL | Q21: EQUATORIAL RENOVAVEIS S.A | R21: EQUTORIAL RENOVAVEIS S.A (NF SERVIÇO) | W21: EQUATORIAL | X21: EQUATORIAL RENOVAVEIS S.A | Y21: EQUTORIAL RENOVAVEIS S.A (NF SERVIÇO)
A22: AREOLINO DE ABREU | B22: 9995.73 | C22: 2947.91 | D22: 2700.9 | E22: =SUM(B22:D22) -> 15644.54 | F22: 773.4436 | H22: AREOLINO DE ABREU | I22: 11664.61 | J22: 4414.85 | K22: 4034.19 | L22: =SUM(I22:K22) -> 20113.65 | M22: 19.7985 | O22: AREOLINO DE ABREU | P22: 13053.63 | Q22: 5175.85 | R22: 4138.72 | S22: =SUM(P22:R22) -> 22368.2 | T22: 19.47325 | V22: AREOLINO DE ABREU | Z22: =SUM(W22:Y22) -> 0
A23: BENTO LEÃO 25 | B23: 10678.04 | C23: 3630.48 | D23: 3078.21 | E23: =SUM(B23:D23) -> 17386.73 | F23: 16.3055 | H23: BENTO LEÃO 25 | I23: 11087.34 | J23: 4531.72 | K23: 3793.66 | L23: =SUM(I23:K23) -> 19412.72 | M23: 19.7985 | O23: BENTO LEÃO 25 | P23: 12378.28 | Q23: 4777.45 | R23: 4019.23 | S23: =SUM(P23:R23) -> 21174.96 | T23: 21.54052 | V23: BENTO LEÃO 25 | Z23: =SUM(W23:Y23) -> 0
A24: BENTO LEÃO 25A | B24: 28657.61 | C24: 9690.75 | D24: 7962.05 | E24: =SUM(B24:D24) -> 46310.41 | F24: 46.52217 | H24: BENTO LEÃO 25A | I24: 30849.45 | J24: 12261.56 | K24: 10243.61 | L24: =SUM(I24:K24) -> 53354.62 | M24: 58.30696 | O24: BENTO LEÃO 25A | P24: 39044.16 | Q24: 16062.86 | R24: 12860.06 | S24: =SUM(P24:R24) -> 67967.08 | T24: 68.85081 | V24: BENTO LEÃO 25A | Z24: =SUM(W24:Y24) -> 0
A25: TOTAL | B25: =SUM(B22:B24) -> 49331.38 | C25: =SUM(C22:C24) -> 16269.14 | D25: =SUM(D22:D24) -> 13741.16 | E25: =SUM(B25:D25) -> 79341.68 | F25: =SUM(F22:F24) -> 836.27127 | H25: TOTAL | I25: =SUM(I22:I24) -> 53601.4 | J25: =SUM(J22:J24) -> 21208.13 | K25: =SUM(K22:K24) -> 18071.46 | L25: =SUM(I25:K25) -> 92880.99 | M25: =SUM(M22:M24) -> 97.90396 | O25: TOTAL | P25: =SUM(P22:P24) -> 64476.07 | Q25: =SUM(Q22:Q24) -> 26016.16 | R25: =SUM(R22:R24) -> 21018.01 | S25: =SUM(P25:R25) -> 111510.24 | T25: =SUM(T22:T24) -> 109.86458 | V25: TOTAL | W25: =SUM(W22:W24) -> 0 | X25: =SUM(X22:X24) -> 0 | Y25: =SUM(Y22:Y24) -> 0 | Z25: =SUM(W25:Y25) -> 0
E26: KWH | F26: =E25/F25 -> 94.87553 | L26: KWH | M26: =L25/M25 -> 948.69493 | S26: KWH | T26: =S25/T25 -> 1014.979
A27: OBSERVAÇÃO: | B27: A economia foi de R$ 14.500,00(ML) e R$ 14.966,76 da folga no carnaval e mês de fevereiro com 2 dias a menos.
A29: RESUMO ANUAL
B30: JAN | C30: FEV | D30: MAR | E30: ABR | F30: MAIO | G30: JUN | H30: JUL | I30: AGO | J30: SET | K30: OUT | L30: NOV | M30: DEZ | N30: TOTAL | O30: MÉDIA
A31: BENTO LEÃO 25 | B31: =E5 -> 15609.74 | C31: =E14 -> 17577.51 | D31: =E23 -> 17386.73 | E31: =L5 -> 18648.19 | F31: =L14 -> 19074.54 | G31: =L23 -> 19412.72 | H31: =S5 -> 20116.92 | I31: =S14 -> 19874.38 | J31: =S23 -> 21174.96 | K31: =Z5 -> 0 | L31: =Z14 -> 0 | M31: =Z23 -> 0 | N31: =SUM(B31:M31) -> 168875.69 | O31: =AVERAGE(B31:M31) -> 14072.974
A32: BENTO LEÃO 25 A | B32: =E6 -> 40865.1 | C32: =E15 -> 37069.6 | D32: =E24 -> 46310.41 | E32: =L6 -> 51535.08 | F32: =L15 -> 49071.66 | G32: =L24 -> 53354.62 | H32: =S6 -> 55095.28 | I32: =S15 -> 48829.48 | J32: =S24 -> 67967.08 | K32: =Z6 -> 0 | L32: =Z15 -> 0 | M32: =Z24 -> 0 | N32: =SUM(B32:M32) -> 450098.31 | O32: =AVERAGE(B32:M32) -> 37508.192
A33: AREOLINO DE ABREU | B33: =E4 -> 15740.55 | C33: =E13 -> 16249.75 | D33: =E22 -> 15644.54 | E33: =L4 -> 14901.95 | F33: =L13 -> 18886.99 | G33: =L22 -> 20113.65 | H33: =S4 -> 21986.71 | I33: =S13 -> 22320.36 | J33: =S22 -> 22368.2 | K33: =Z4 -> 0 | L33: =Z13 -> 0 | M33: =Z22 -> 0 | N33: =SUM(B33:M33) -> 168212.7 | O33: =AVERAGE(B33:M33) -> 14017.725
A34: TOTAL MÊS | B34: =SUM(B31:B33) -> 72215.39 | C34: =SUM(C31:C33) -> 70896.86 | D34: =SUM(D31:D33) -> 79341.68 | E34: =SUM(E31:E33) -> 85085.22 | F34: =SUM(F31:F33) -> 87033.19 | G34: =SUM(G31:G33) -> 92880.99 | H34: =SUM(H31:H33) -> 97198.91 | I34: =SUM(I31:I33) -> 91024.22 | ... M34: =SUM(M31:M33) -> 0 | N34: =SUM(B34:M34) -> 787186.7 | O34: =SUM(O31:O33) -> 65598.892
A35: ECONOMIA | B35: =#REF! -> #REF! | C35: =#REF! -> #REF! | D35: =#REF! -> #REF! | E35: =M7 -> 914.75806 | G35: =M25 -> 97.90396 | H35: =T7 -> 96.57034 | I35: =T16 -> 88.8765 | J35: =T25 -> 109.86458 | K35: =Z7 -> 0 | L35: =Z16 -> 0 | M35: =AA25 -> 0 | N35: =SUM(B35:M35) -> #REF! | O35: =N35/8 -> #REF!
A37: ENERGIA | B37: JAN | C37: FEV | D37: MAR | E37: ABR | G37: JUN | H37: JUL | I37: AGO | J37: SET | K37: OUT | L37: NOV | M37: DEZ | N37: TOTAL | O37: MÉDIA
A38: 2025 | B38: =E7 -> 72215.39 | C38: =E16 -> 79235.16 | D38: =E25 -> 79341.68 | E38: =L7 -> 85085.22 | G38: =L25 -> 92880.99 | H38: =S7 -> 97198.91 | I38: =S16 -> 91024.22 | J38: =S25 -> 111510.24 | K38: =Z7 -> 0 | L38: =Z16 -> 0 | M38: =Z25 -> 0 | N38: =N33 -> 168212.7 | O38: =N38/12 -> 14017.725
A39: 2024 | B39: =B34 -> 72215.39 | C39: =C34 -> 70896.86 | D39: =D34 -> 79341.68 | E39: =E34 -> 85085.22 | G39: =G34 -> 92880.99 | H39: =H34 -> 97198.91 | I39: =I34 -> 91024.22 | J39: =J34 -> 111510.24 | K39: =K34 -> 0 | L39: =L34 -> 0 | M39: =M34 -> 0 | N39: =N34 -> 787186.7 | O39: =N39/12 -> 65598.892
A40: 2023 | B40: ='[1]ENERGIA 2023 - LIVRE'!$B$37 -> 62597.68 | C40: ='[1]ENERGIA 2023 - LIVRE'!$C$37 -> 62244.93 | D40: ='[1]ENERGIA 2023 - LIVRE'!$D$37 -> 46282.96 | E40: ='[1]ENERGIA 2023 - LIVRE'!$E$37 -> 54003.36 | G40: ='[1]ENERGIA 2023 - LIVRE'!$G$37 -> 65134.19 | H40: ='[1]ENERGIA 2023 - LIVRE'!$H$37 -> 65293.94 | I40: ='[1]ENERGIA 2023 - LIVRE'!$I$37 -> 64927.98 | J40: ='[1]ENERGIA 2023 - LIVRE'!$J$37 -> 74762.17 | K40: ='[1]ENERGIA 2023 - LIVRE'!$K$37 -> 71904.87 | L40: ='[1]ENERGIA 2023 - LIVRE'!$L$37 -> 73080.08 | M40: ='[1]ENERGIA 2023 - LIVRE'!$M$37 -> 66751.19 | N40: =SUM(B40:M40) -> 706983.35 | O40: =N40/12 -> 58915.279
A41: 2022 | B41: 84625.79 | C41: 95776.52 | D41: 98234.23 | E41: 82765.8 | G41: 73467.53 | H41: 71232.93 | I41: 78602.33 | J41: 74305.13 | K41: 83561.7 | L41: 68892.09 | M41: 24875.48 | N41: =SUM(A41:M41) -> 838361.53 | O41: =N41/12 -> 69863.461
A42: DIFERENÇA (2024-2023) | B42: =B40-B39 -> -9617.71 | C42: =C40-C39 -> -8651.93 | D42: =D40-D39 -> -33058.72 | E42: =E40-E39 -> -31081.86 | G42: =G40-G39 -> -27746.8 | H42: =H40-H39 -> -31904.97 | I42: =I40-I39 -> -26096.24 | J42: =J40-J39 -> -36748.07 | K42: =K40-K39 -> 71904.87 | L42: =L40-L39 -> 73080.08 | M42: =M40-M39 -> 66751.19 | N42: =N40-N39 -> -80203.35

Sheet ENERGIA 2026- LIVRE
A1: ENERGIA 2026 | H1: ENERGIA 2026 | O1: ENERGIA 2026 | V1: ENERGIA 2026
B2: JANEIRO | E2: TOTAL | I2: ABRIL | L2: TOTAL | P2: JULHO | S2: TOTAL | W2: OUTUBRO | Z2: TOTAL
B3: EQUATORIAL | C3: EQUATORIAL RENOVAVEIS S.A | D3: EQUTORIAL RENOVAVEIS S.A (NF SERVIÇO) | F3: ECONOMIA | I3: EQUATORIAL | J3: EQUATORIAL RENOVAVEIS S.A | K3: EQUTORIAL RENOVAVEIS S.A (NF SERVIÇO) | M3: ECONOMIA | P3: EQUATORIAL | Q3: EQUATORIAL RENOVAVEIS S.A | R3: EQUTORIAL RENOVAVEIS S.A (NF SERVIÇO) | T3: ECONOMIA | W3: EQUATORIAL | X3: EQUATORIAL RENOVAVEIS S.A | Y3: EQUTORIAL RENOVAVEIS S.A (NF SERVIÇO) | AA3: ECONOMIA
A4: AREOLINO DE ABREU | B4: 9132.27 | C4: 3600.54 | D4: 3007.78 | E4: =SUM(B4:D4) -> 15740.59 | F4: =#REF!-#REF! -> #REF! | H4: AREOLINO DE ABREU | I4: 8554.71 | J4: 3352.83 | L4: =SUM(I4:K4) -> 11907.54 | M4: =#REF!-#REF! -> #REF! | O4: AREOLINO DE ABREU | P4: 13310.88 | Q4: 4986.61 | R4: 3689.22 | S4: =SUM(P4:R4) -> 21986.71 | T4: =#REF!-#REF! -> #REF! | V4: AREOLINO DE ABREU | Z4: =SUM(W4:Y4) -> 0 | AA4: =#REF!-Z4 -> #REF!
A5: BENTO LEÃO 25 | B5: 8969.62 | C5: 3592.57 | D5: 3047.55 | E5: =SUM(B5:D5) -> 15609.74 | F5: =#REF!-#REF! -> #REF! | H5: BENTO LEÃO 25 | I5: 30158.63 | J5: 4265.54 | L5: =SUM(I5:K5) -> 34424.17 | M5: =#REF!-#REF! -> #REF! | O5: BENTO LEÃO 25 | P5: 11177.82 | Q5: 4596.15 | R5: 4342.95 | S5: =SUM(P5:R5) -> 20116.92 | T5: =#REF!-#REF! -> #REF! | V5: BENTO LEÃO 25 | Z5: =SUM(W5:Y5) -> 0 | AA5: =#REF!-Z5 -> #REF!
A6: BENTO LEÃO 25A | B6: 24013 | C6: 9229.54 | D6: 7622.56 | E6: =SUM(B6:D6) -> 40865.1 | F6: =#REF!-#REF! -> #REF! | H6: BENTO LEÃO 25A | I6: 10871.41 | J6: 12076.31 | L6: =SUM(I6:K6) -> 22947.72 | M6: =#REF!-#REF! -> #REF! | O6: BENTO LEÃO 25A | P6: 31820.47 | Q6: 13037.85 | R6: 10236.96 | S6: =SUM(P6:R6) -> 55095.28 | T6: =#REF!-#REF! -> #REF! | V6: BENTO LEÃO 25A | Z6: =SUM(W6:Y6) -> 0 | AA6: =#REF!-Z6 -> #REF!
A7: TOTAL | B7: =SUM(B4:B6) -> 42114.89 | C7: =SUM(C4:C6) -> 16422.65 | D7: =SUM(D4:D6) -> 13677.89 | E7: =SUM(B7:D7) -> 72215.43 | F7: =SUM(F4:F6) -> #REF! | H7: TOTAL | I7: =SUM(I4:I6) -> 49584.75 | J7: =SUM(J4:J6) -> 19694.68 | K7: =SUM(K4:K6) -> 0 | L7: =SUM(I7:K7) -> 69279.43 | M7: =SUM(M4:M6) -> #REF! | O7: TOTAL | P7: =SUM(P4:P6) -> 56309.17 | Q7: =SUM(Q4:Q6) -> 22620.61 | R7: =SUM(R4:R6) -> 18269.13 | S7: =SUM(P7:R7) -> 97198.91 | T7: =SUM(T4:T6) -> #REF! | V7: TOTAL | W7: =SUM(W5:W6) -> 0 | X7: =SUM(X4:X6) -> 0 | Y7: =SUM(Y4:Y6) -> 0 | Z7: =SUM(W7:Y7) -> 0 | AA7: =SUM(AA4:AA6) -> #REF!
A10: ENERGIA 2026 | H10: ENERGIA 2026 | O10: ENERGIA 2026 | V10: ENERGIA 2026
B11: FEVEREIRO | E11: TOTAL | I11: MAIO | L11: TOTAL | P11: AGOSTO | S11: TOTAL | W11: NOVEMBRO | Z11: TOTAL
B12: EQUATORIAL | C12: EQUATORIAL RENOVAVEIS S.A | D12: EQUTORIAL RENOVAVEIS S.A (NF SERVIÇO) | F12: ECONOMIA | I12: EQUATORIAL | J12: EQUATORIAL RENOVAVEIS S.A | K12: EQUTORIAL RENOVAVEIS S.A (NF SERVIÇO) | M12: ECONOMIA | P12: EQUATORIAL | Q12: EQUATORIAL RENOVAVEIS S.A | R12: EQUTORIAL RENOVAVEIS S.A (NF SERVIÇO) | T12: ECONOMIA | W12: EQUATORIAL | X12: EQUATORIAL RENOVAVEIS S.A | Y12: EQUTORIAL RENOVAVEIS S.A (NF SERVIÇO) | AA12: ECONOMIA
A13: AREOLINO DE ABREU | B13: 9317.07 | C13: 3799.08 | D13: 3133.6 | E13: =SUM(B13:D13) -> 16249.75 | F13: =#REF!-#REF! -> #REF! | H13: AREOLINO DE ABREU | I13: 10906.52 | J13: 4265.21 | K13: 3715.26 | L13: =SUM(I13:K13) -> 18886.99 | M13: =#REF!-#REF! -> #REF! | O13: AREOLINO DE ABREU | P13: 13639.91 | Q13: 5015.38 | R13: 3665.07 | S13: =SUM(P13:R13) -> 22320.36 | T13: =#REF!-#REF! -> #REF! | V13: AREOLINO DE ABREU | Z13: =SUM(W13:Y13) -> 0 | AA13: =#REF!-Z13 -> #REF!
A14: BENTO LEÃO 25 | B14: 10020.32 | C14: 4176.94 | D14: 3380.25 | E14: =SUM(B14:D14) -> 17577.51 | F14: =#REF!-#REF! -> #REF! | H14: BENTO LEÃO 25 | I14: 10784.49 | J14: 4623.81 | K14: 3666.24 | L14: =SUM(I14:K14) -> 19074.54 | M14: =#REF!-#REF! -> #REF! | O14: BENTO LEÃO 25 | P14: 11060.18 | Q14: 4560.77 | R14: 4253.43 | S14: =SUM(P14:R14) -> 19874.38 | T14: =#REF!-#REF! -> #REF! | V14: BENTO LEÃO 25 | Z14: =SUM(W14:Y14) -> 0 | AA14: =#REF!-Z14 -> #REF!
A15: BENTO LEÃO 25A | B15: 26386.74 | C15: 10682.86 | D15: 8338.3 | E15: =SUM(B15:C15) -> 37069.6 | F15: =#REF!-#REF! -> #REF! | H15: BENTO LEÃO 25A | I15: 27645.34 | J15: 12155.79 | K15: 9270.53 | L15: =SUM(I15:K15) -> 49071.66 | M15: =#REF!-#REF! -> #REF! | O15: BENTO LEÃO 25A | P15: 28522.86 | Q15: 11423.33 | R15: 8883.29 | S15: =SUM(P15:R15) -> 48829.48 | T15: =#REF!-#REF! -> #REF! | V15: BENTO LEÃO 25A | Z15: =SUM(W15:Y15) -> 0 | AA15: =#REF!-Z15 -> #REF!
A16: TOTAL | B16: =SUM(B13:B15) -> 45724.13 | C16: =SUM(C13:C15) -> 18658.88 | D16: =SUM(D13:D15) -> 14852.15 | E16: =SUM(B16:D16) -> 79235.16 | F16: =SUM(F13:F15) -> #REF! | H16: TOTAL | I16: =SUM(I14:I15) -> 38429.83 | J16: =SUM(J13:J15) -> 21044.81 | K16: =SUM(K13:K15) -> 16652.03 | L16: =SUM(I16:K16) -> 76126.67 | M16: =SUM(M13:M15) -> #REF! | O16: TOTAL | P16: =SUM(P13:P15) -> 53222.95 | Q16: =SUM(Q13:Q15) -> 20999.48 | R16: =SUM(R13:R15) -> 16801.79 | S16: =SUM(P16:R16) -> 91024.22 | T16: =SUM(T13:T15) -> #REF! | V16: TOTAL | W16: =SUM(W14:W15) -> 0 | X16: =SUM(X13:X15) -> 0 | Y16: =SUM(Y14:Y15) -> 0 | Z16: =SUM(W16:Y16) -> 0 | AA16: =SUM(AA13:AA15) -> #REF!
F17: =(B15+C15)/51910.93 -> 0.71410009
A19: ENERGIA 2025 | H19: ENERGIA 2025 | O19: ENERGIA 2025 | V19: ENERGIA 2025
B20: MARÇO | E20: TOTAL | I20: JUNHO | L20: TOTAL | P20: SETEMBRO | S20: TOTAL | W20: DEZEMBRO | Z20: TOTAL
B21: EQUATORIAL | C21: EQUATORIAL RENOVAVEIS S.A | D21: EQUTORIAL RENOVAVEIS S.A (NF SERVIÇO) | F21: ECONOMIA | I21: EQUATORIAL | J21: EQUATORIAL RENOVAVEIS S.A | K21: EQUTORIAL RENOVAVEIS S.A (NF SERVIÇO) | M21: ECONOMIA | P21: EQUATORIAL | Q21: EQUATORIAL RENOVAVEIS S.A | R21: EQUTORIAL RENOVAVEIS S.A (NF SERVIÇO) | T21: ECONOMIA | W21: EQUATORIAL | X21: EQUATORIAL RENOVAVEIS S.A | Y21: EQUTORIAL RENOVAVEIS S.A (NF SERVIÇO) | AA21: ECONOMIA
A22: AREOLINO DE ABREU | B22: 9995.73 | C22: 2947.91 | D22: 2700.9 | E22: =SUM(B22:D22) -> 15644.54 | F22: =#REF!-#REF! -> #REF! | H22: AREOLINO DE ABREU | I22: 11664.61 | J22: 4414.85 | K22: 4034.19 | L22: =SUM(I22:K22) -> 20113.65 | M22: =#REF!-#REF! -> #REF! | O22: AREOLINO DE ABREU | P22: 13053.63 | Q22: 5175.85 | R22: 4138.72 | S22: =SUM(P22:R22) -> 22368.2 | T22: =#REF!-#REF! -> #REF! | V22: AREOLINO DE ABREU | Z22: =SUM(W22:Y22) -> 0 | AA22: =#REF!-Z22 -> #REF!
A23: BENTO LEÃO 25 | B23: 10678.04 | C23: 3630.48 | D23: 3078.21 | E23: =SUM(B23:D23) -> 17386.73 | F23: =#REF!-#REF! -> #REF! | H23: BENTO LEÃO 25 | I23: 11087.34 | J23: 4531.72 | K23: 3793.66 | L23: =SUM(I23:K23) -> 19412.72 | M23: =#REF!-#REF! -> #REF! | O23: BENTO LEÃO 25 | P23: 12378.28 | Q23: 4777.45 | R23: 4019.23 | S23: =SUM(P23:R23) -> 21174.96 | T23: =#REF!-#REF! -> #REF! | V23: BENTO LEÃO 25 | Z23: =SUM(W23:Y23) -> 0 | AA23: =#REF!-Z23 -> #REF!
A24: BENTO LEÃO 25A | B24: 28657.61 | C24: 9690.75 | D24: 7962.05 | E24: =SUM(B24:D24) -> 46310.41 | F24: =#REF!-#REF! -> #REF! | H24: BENTO LEÃO 25A | I24: 30849.45 | J24: 12261.56 | K24: 10243.61 | L24: =SUM(I24:K24) -> 53354.62 | M24: =#REF!-#REF! -> #REF! | O24: BENTO LEÃO 25A | P24: 39044.16 | Q24: 16062.86 | R24: 12860.06 | S24: =SUM(P24:R24) -> 67967.08 | T24: =#REF!-Z24 -> #REF! | V24: BENTO LEÃO 25A | Z24: =SUM(W24:Y24) -> 0 | AA24: =#REF!-#REF! -> #REF!
A25: TOTAL | B25: =SUM(B22:B24) -> 49331.38 | C25: =SUM(C22:C24) -> 16269.14 | D25: =SUM(D22:D24) -> 13741.16 | E25: =SUM(B25:D25) -> 79341.68 | F25: =SUM(F22:F24) -> #REF! | H25: TOTAL | I25: =SUM(I22:I24) -> 53601.4 | J25: =SUM(J22:J24) -> 21208.13 | K25: =SUM(K22:K24) -> 18071.46 | L25: =SUM(I25:K25) -> 92880.99 | M25: =SUM(M22:M24) -> #REF! | O25: TOTAL | P25: =SUM(P22:P24) -> 64476.07 | Q25: =SUM(Q22:Q24) -> 26016.16 | R25: =SUM(R22:R24) -> 21018.01 | S25: =SUM(P25:R25) -> 111510.24 | T25: =SUM(T22:T24) -> #REF! | V25: TOTAL | W25: =SUM(W22:W24) -> 0 | X25: =SUM(X22:X24) -> 0 | Y25: =SUM(Y22:Y24) -> 0 | Z25: =SUM(W25:Y25) -> 0 | AA25: =SUM(AA22:AA24) -> #REF!
A26: OBSERVAÇÃO:
A28: RESUMO ANUAL
B29: JAN | C29: FEV | D29: MAR | E29: ABR | F29: MAI | G29: JUN | H29: JUL | I29: AGO | J29: SET | K29: OUT | L29: NOV | M29: DEZ | N29: TOTAL | O29: MÉDIA
A30: BENTO LEÃO 25 | B30: =E5 -> 15609.74 | C30: =E14 -> 17577.51 | D30: =E23 -> 17386.73 | E30: =L5 -> 34424.17 | F30: =L14 -> 19074.54 | G30: =L23 -> 19412.72 | H30: =S5 -> 20116.92 | I30: =S14 -> 19874.38 | J30: =S23 -> 21174.96 | K30: =Z5 -> 0 | L30: =Z14 -> 0 | M30: =Z23 -> 0 | N30: =SUM(B30:M30) -> 184651.67 | O30: =AVERAGE(B30:M30) -> 15387.639
A31: BENTO LEÃO 25 A | B31: =E6 -> 40865.1 | C31: =E15 -> 37069.6 | D31: =E24 -> 46310.41 | E31: =L6 -> 22947.72 | F31: =L15 -> 49071.66 | G31: =L24 -> 53354.62 | H31: =S6 -> 55095.28 | I31: =S15 -> 48829.48 | J31: =S24 -> 67967.08 | K31: =Z6 -> 0 | L31: =Z15 -> 0 | M31: =Z24 -> 0 | N31: =SUM(B31:M31) -> 421510.95 | O31: =AVERAGE(B31:M31) -> 35125.912
A32: AREOLINO DE ABREU | B32: =E4 -> 15740.59 | C32: =E13 -> 16249.75 | D32: =E22 -> 15644.54 | E32: =L4 -> 11907.54 | F32: =L13 -> 18886.99 | G32: =L22 -> 20113.65 | H32: =S4 -> 21986.71 | I32: =S13 -> 22320.36 | J32: =S22 -> 22368.2 | K32: =Z4 -> 0 | L32: =Z13 -> 0 | M32: =Z22 -> 0 | N32: =SUM(B32:M32) -> 165218.33 | O32: =AVERAGE(B32:M32) -> 13768.194
A33: TOTAL MÊS | B33: =SUM(B30:B32) -> 72215.43 | C33: =SUM(C30:C32) -> 70896.86 | D33: =SUM(D30:D32) -> 79341.68 | E33: =SUM(E30:E32) -> 69279.43 | F33: =SUM(F30:F32) -> 87033.19 | G33: =SUM(G30:G32) -> 92880.99 | H33: =SUM(H30:H32) -> 97198.91 | I33: =SUM(I30:I32) -> 91024.22 | ... M33: =SUM(M30:M32) -> 0 | N33: =SUM(B33:M33) -> 771380.95 | O33: =SUM(O30:O32) -> 64281.746
A34: ECONOMIA | B34: =F7 -> #REF! | C34: =F16 -> #REF! | D34: =F25 -> #REF! | E34: =M7 -> #REF! | F34: =M16 -> #REF! | G34: =M25 -> #REF! | H34: =T7 -> #REF! | I34: =T16 -> #REF! | J34: =T25 -> #REF! | K34: =Z7 -> 0 | L34: =Z16 -> 0 | M34: =AA25 -> #REF! | N34: =SUM(B34:M34) -> #REF! | O34: =N34/8 -> #REF!
A36: ENERGIA | B36: JAN | C36: FEV | D36: MAR | E36: ABR | F36: MAI | G36: JUN | H36: JUL | I36: AGO | J36: SET | K36: OUT | L36: NOV | M36: DEZ | N36: TOTAL | O36: MÉDIA
A37: 2025 | B37: =E7 -> 72215.43 | C37: =E16 -> 79235.16 | D37: =E25 -> 79341.68 | E37: =L7 -> 69279.43 | F37: =L16 -> 76126.67 | G37: =L25 -> 92880.99 | H37: =S7 -> 97198.91 | I37: =S16 -> 91024.22 | J37: =S25 -> 111510.24 | K37: =Z7 -> 0 | L37: =Z16 -> 0 | M37: =Z25 -> 0 | N37: =N32 -> 165218.33 | O37: =N37/12 -> 13768.194
A38: 2024 | B38: =B33 -> 72215.43 | C38: =C33 -> 70896.86 | D38: =D33 -> 79341.68 | E38: =E33 -> 69279.43 | F38: =F33 -> 87033.19 | G38: =G33 -> 92880.99 | H38: =H33 -> 97198.91 | I38: =I33 -> 91024.22 | ... N38: =N33 -> 771380.95 | O38: =N38/12 -> 64281.746
A39: 2023 | B39: ='[1]ENERGIA 2023 - LIVRE'!$B$37 -> 62597.68 | C39: ='[1]ENERGIA 2023 - LIVRE'!$C$37 -> 62244.93 | D39: ='[1]ENERGIA 2023 - LIVRE'!$D$37 -> 46282.96 | E39: ='[1]ENERGIA 2023 - LIVRE'!$E$37 -> 54003.36 | F39: ='[1]ENERGIA 2023 - LIVRE'!$F$37 -> 53845.8 | G39: ='[1]ENERGIA 2023 - LIVRE'!$G$37 -> 65134.19 | H39: ='[1]ENERGIA 2023 - LIVRE'!$H$37 -> 65293.94 | I39: ='[1]ENERGIA 2023 - LIVRE'!$I$37 -> 64927.98 | J39: ='[1]ENERGIA 2023 - LIVRE'!$J$37 -> 74762.17 | K39: ='[1]ENERGIA 2023 - LIVRE'!$K$37 -> 71904.87 | L39: ='[1]ENERGIA 2023 - LIVRE'!$L$37 -> 73080.08 | M39: ='[1]ENERGIA 2023 - LIVRE'!$M$37 -> 66751.19 | N39: =SUM(B39:M39) -> 760829.15 | O39: =N39/12 -> 63402.429
A40: 2022 | B40: 84625.79 | C40: 95776.52 | D40: 98234.23 | E40: 82765.8 | F40: 67715.9 | G40: 73467.53 | H40: 71232.93 | I40: 78602.33 | J40: 74305.13 | K40: 83561.7 | L40: 68892.09 | M40: 24875.48 | N40: =SUM(A40:M40) -> 906077.43 | O40: =N40/12 -> 75506.452
A41: DIFERENÇA (2024-2023) | B41: =B39-B38 -> -9617.75 | C41: =C39-C38 -> -8651.93 | D41: =D39-D38 -> -33058.72 | E41: =E39-E38 -> -15276.07 | F41: =F39-F38 -> -33187.39 | G41: =G39-G38 -> -27746.8 | H41: =H39-H38 -> -31904.97 | I41: =I39-I38 -> -26096.24 | ... N41: =N39-N38 -> -10551.8
D46: equatorial | E46: equatorial renováveis S.A | F46: equatorial renováveis S.A (serviços)
D47: =SUM(B7,B16,B25,I7,I16,I25,P7,P16,P25,W7,W16) -> 452794.57 | E47: =SUM(C7,C16,C25,J7,J16,J25,Q7,Q16,Q25,X7) -> 182934.54 | F47: =SUM(D7,D16,D25,K7,K16,K25,R7,R16,R25,Y7,Y16) -> 133083.62
D48: =SUM(B7,B16,B25,I7,I16,I25,P7,P16,P25,W7,W16) -> 452794.57 | E48: =SUM(C7,C16,C25,J7,J16,J25,Q7,Q16,Q25,X7) -> 182934.54 | F48: =SUM(D7,D16,D25,K7,K16,K25,R7,R16,R25,Y7,Y16) -> 133083.62

Sheet painel

Sheet ÁGUA 2026
B1: CONSUMO (M³)
A2: HIDROMETRO | B2: ENDEREÇO | C2: LOCAL DE ABASTECIMENTO | D2: JAN | E2: FEV | F2: MAR | G2: ABR | H2: MAI | I2: JUN | J2: JULHO | K2: AGOS | L2: SET | M2: OUT | N2: NOV | O2: DEZ | P2: TOTAL ANO | Q2: MÉDIA
A3: E15N001061 | B3: BENTO LEÃO 25 A | C3: PRODUÇÃO/STA | D3: 276 | G3: 387 | H3: 393 | I3: 406 | J3: 509 | K3: 345 | P3: =SUM(D3:O3) -> 2316 | Q3: =SUM(D3:O3)/9 -> 257.33333
A4: B11L006108 | B4: JOSÉ GUIMARÃES 350 | C4: ADM/CQ | D4: 56 | E4: 46 | F4: 55 | G4: 10 | H4: 50 | I4: 37 | J4: 69 | K4: 82 | P4: =SUM(D4:O4) -> 405 | Q4: =SUM(D4:O4)/9 -> 45
A5: Y12L233313 | B5: JOSE GUIMARÃES 385 | C5: MANUTENÇÃO | D5: 10 | E5: 10 | F5: 10 | G5: 10 | H5: 10 | I5: 10 | J5: 10 | K5: 10 | P5: =SUM(D5:O5) -> 80 | Q5: =SUM(D5:O5)/9 -> 8.8888889
A6: B11L006086 | B6: AREOLINO DE ABREU 306 | C6: SÓLIDOS/BATATA/PCP COMPRAS | D6: 39 | E6: 40 | H6: 25 | I6: 24 | J6: 46 | K6: 45 | P6: =SUM(D6:O6) -> 219 | Q6: =SUM(D6:O6)/9 -> 24.333333
B8: VALOR
A9: HIDROMETRO | B9: ENDEREÇO | C9: LOCAL DE ABASTECIMENTO | D9: JAN | E9: FEV | F9: MAR | G9: ABR | H9: MAI | I9: JUN | J9: JULHO | K9: AGOS | L9: SET | M9: OUT | N9: NOV | O9: DEZ | P9: TOTAL ANO | Q9: MEDIA
A10: E15N001061 | B10: BENTO LEÃO - 25 A | C10: PRODUÇÃO/STA | D10: 5885.3 | E10: 106.36 | F10: 10577.1 | G10: 8750.6 | H10: 8748.38 | I10: 9187.62 | J10: 11572.9 | K10: 7774.99 | P10: 5885.3 | Q10: =SUM(D10:O10)/9 -> 6955.9167
A11: B11L006108 | B11: JOSÉ GUIMARÃES - 350 | C11: ADM/CQ | D11: 1096.59 | E11: 1108.6 | F11: 943.37 | G11: 108.57 | H11: 923.59 | I11: 642.32 | J11: 1383.37 | K11: 1684.43 | P11: =SUM(D11:O11) -> 7890.84 | Q11: =SUM(D11:O11)/9 -> 876.76
A12: Y12L233313 | B12: JOSE GUIMARÃES - 385 | C12: MANUTENÇÃO | D12: 108.77 | E12: 106.36 | F12: 112.37 | G12: 108.57 | H12: 106 | I12: 108.57 | J12: 108.57 | K12: 108.57 | P12: =SUM(D12:O12) -> 867.78 | Q12: =SUM(D12:O12)/9 -> 96.42
A13: B11L006086 | B13: AREOLINO DE ABREU - 306 | C13: SÓLIDOS/BATATA/PCP COMPRAS | D13: 813.04 | E13: 901.47 | H13: 375.06 | I13: 363.31 | J13: 850.74 | K13: 827.58 | P13: =SUM(D13:O13) -> 4131.2 | Q13: =SUM(D13:O13)/9 -> 459.02222
C14: TOTAL | D14: =SUM(D10:D13) -> 7903.7 | E14: =SUM(E10:E13) -> 2222.79 | F14: =SUM(F10:F13) -> 11632.84 | G14: =SUM(G10:G13) -> 8967.74 | H14: =SUM(H10:H13) -> 10153.03 | I14: =SUM(I10:I13) -> 10301.82 | J14: =SUM(J10:J13) -> 13915.58 | K14: =SUM(K10:K13) -> 10395.57 | ... O14: =SUM(O10:O13) -> 0 | P14: =SUM(D14:O14) -> 75493.07 | Q14: =SUM(D14:O14)/9 -> 8388.1189
A16: UND.CONSUMIDORA | B16: MATRICULA | C16: MATRICULA | D16: HIDROMETRO | E16: LOCALIZAÇÃO
A17: AREOLINO DE ABREU - 306 | B17: 2737849-7 | C17: 227378497-4 | D17: A22FA0234889 | E17: 01-600-10-500-0155
A18: BENTO LEÃO - 25 A | B18: 375264-0 | C18: 203752640-0 | D18: E15N001061 | E18: 01-400-10-600-1380
A19: JOSÉ GUIMARÃES - 350 | B19: 26962454-2 | C19: 226962454-2 | D19: B11L006108 | E19: 01-400-10-600-1400
A20: JOSÉ GUIMARÃES - 385 | B20: 360983-9 | C20: 203585751-6 | D20: A98N160319 | E20: 01-400-10-600-1395
